<?xml version="1.0"?>
<robot xmlns:xacro="http://www.ros.org/wiki/xacro">
    
    <xacro:include filename="macro_inertia.xacro"/>
    
    <!-- Colors -->
    
    <material name="black">
        <color rgba="0.0 0.0 0.0 1.0"/>
    </material>

    <material name="dark">
        <color rgba="0.3 0.3 0.3 1.0"/>
    </material>
    <material name="light_black">
        <color rgba="0.4 0.4 0.4 1.0"/>
    </material>

    <material name="blue">
        <color rgba="0.0 0.0 0.8 1.0"/>
    </material>

    <material name="green">
        <color rgba="0.0 0.8 0.0 1.0"/>
    </material>

    <material name="grey">
        <color rgba="0.5 0.5 0.5 1.0"/>
    </material>

    <material name="yellow">
        <color rgba="1.0 1.0 0.0 1.0"/>
    </material>

    <material name="orange">
        <color rgba="${255/255} ${108/255} ${10/255} 1.0"/>
    </material>

    <material name="brown">
        <color rgba="${222/255} ${207/255} ${195/255} 1.0"/>
    </material>

    <material name="red">
        <color rgba="0.8 0.0 0.0 1.0"/>
    </material>

    <material name="white">
        <color rgba="1.0 1.0 1.0 1.0"/>
    </material>


    <!-- Base Link -->
    <link name="base_link"></link>

    <!-- Base Footprint -->
    <joint name="base_footprint_joint" type="fixed">
        <parent link="base_link"/>
        <child link="base_footprint"/>
        <origin xyz="0 0 0" rpy="0 0 0"/>
    </joint>

    <link name="base_footprint"></link>

    <!-- CHASSIS LINK-->
    <joint name="chassis_joint" type="fixed">
        <parent link ="base_link"/>
        <child link ="chassis"/>
        <origin xyz="-0.1 0 0"/>
    </joint>
    
    <link name="chassis">
        <visual>
            <origin xyz="0.1 0 0.05"/>        
            <geometry>
                <box size="0.2 0.2 0.1"/>     
            </geometry>
            <material name="yellow"/>
        </visual>
        <collision>
            <origin xyz="0.1 0 0.05"/>
            <geometry>
                <box size="0.2 0.2 0.1"/>
            </geometry>
        </collision>
        <xacro:inertial_box mass="0.2" x="0.2" y="0.2" z="0.1">
            <origin xyz="0.225 0 0.025" rpy="0 0 0"/>
        </xacro:inertial_box>
    </link>
    
    <!-- LEFT WHEEL LINK -->

    <joint name="left_wheel_joint" type="continuous">
        <parent link="base_link"/>
        <child link="left_wheel"/>
        <origin xyz="-0.035 0.125 0.04" rpy="-${pi/2} 0 0" />
        <axis xyz="0 0 1"/>
    </joint>

    <link name="left_wheel">
        <visual>
            <geometry>
                <cylinder radius="0.06" length="0.02"/>
            </geometry>
            <material name="blue"/>
        </visual>
        <collision>
            <geometry>
                <cylinder radius="0.06" length="0.02"/>
            </geometry>
        </collision>
        <xacro:inertial_cylinder mass="0.1" length="0.02" radius="0.06">
            <origin xyz="0 0 0" rpy="0 0 0"/>
        </xacro:inertial_cylinder>
    </link>

    <!-- RIGHT WHEEL LINK -->

    <joint name="right_wheel_joint" type="continuous">
        <parent link="base_link"/>
        <child link="right_wheel"/>
        <origin xyz="-0.035 -0.125 0.04" rpy="${pi/2} 0 0" />
        <axis xyz="0 0 -1"/>
    </joint>

    <link name="right_wheel">
        <visual>
            <geometry>
                <cylinder radius="0.06" length="0.02"/>
            </geometry>
            <material name="blue"/>
        </visual>
        <collision>
            <geometry>
                <cylinder radius="0.06" length="0.02"/>
            </geometry>
        </collision>
        <xacro:inertial_cylinder mass="0.1" length="0.02" radius="0.06">
            <origin xyz="0 0 0" rpy="0 0 0"/>
        </xacro:inertial_cylinder>
    </link>

    <!-- CASTER WHEEL LINK -->

    <joint name="caster_wheel_joint" type="fixed">
        <parent link="base_link"/>        
        <child link="caster_wheel"/>
        <origin xyz="0.061 0.0 0.0"/>
    </joint>

    <link name="caster_wheel">
        <visual>
            <geometry>
                <sphere radius="0.021"/>
            </geometry>
            <material name="red"/>
        </visual>
        <collision>
            <geometry>
                <sphere radius="0.021"/>
            </geometry>

            <surface>
                <friction>
                    <ode>
                        <mu>0.001</mu>
                        <mu2>0.001</mu2>
                    </ode>
                </friction>
            </surface>

        </collision>
        <xacro:inertial_sphere mass="0.1" radius="0.021">
            <origin xyz="0 0 0" rpy="0 0 0"/>
        </xacro:inertial_sphere>
    </link>

    <gazebo reference="caster_wheel">
        <mu1 value="0.001"/>
        <mu2 value="0.001"/>
    </gazebo>

</robot>
